INFO:     Will watch for changes in these directories: ['/app']
INFO:     Uvicorn running on http://0.0.0.0:8110 (Press CTRL+C to quit)
INFO:     Started reloader process [7] using WatchFiles
Process SpawnProcess-1:
Traceback (most recent call last):
  File "/usr/local/lib/python3.12/multiprocessing/process.py", line 314, in _bootstrap
    self.run()
  File "/usr/local/lib/python3.12/multiprocessing/process.py", line 108, in run
    self._target(*self._args, **self._kwargs)
  File "/usr/local/lib/python3.12/site-packages/uvicorn/_subprocess.py", line 80, in subprocess_started
    target(sockets=sockets)
  File "/usr/local/lib/python3.12/site-packages/uvicorn/server.py", line 66, in run
    return asyncio.run(self.serve(sockets=sockets))
           ^^^^^^^^^^^^^^^^^^^^^^^^^^^^^^^^^^^^^^^^
  File "/usr/local/lib/python3.12/asyncio/runners.py", line 195, in run
    return runner.run(main)
           ^^^^^^^^^^^^^^^^
  File "/usr/local/lib/python3.12/asyncio/runners.py", line 118, in run
    return self._loop.run_until_complete(task)
           ^^^^^^^^^^^^^^^^^^^^^^^^^^^^^^^^^^^
  File "uvloop/loop.pyx", line 1518, in uvloop.loop.Loop.run_until_complete
  File "/usr/local/lib/python3.12/site-packages/uvicorn/server.py", line 70, in serve
    await self._serve(sockets)
  File "/usr/local/lib/python3.12/site-packages/uvicorn/server.py", line 77, in _serve
    config.load()
  File "/usr/local/lib/python3.12/site-packages/uvicorn/config.py", line 435, in load
    self.loaded_app = import_from_string(self.app)
                      ^^^^^^^^^^^^^^^^^^^^^^^^^^^^
  File "/usr/local/lib/python3.12/site-packages/uvicorn/importer.py", line 22, in import_from_string
    raise exc from None
  File "/usr/local/lib/python3.12/site-packages/uvicorn/importer.py", line 19, in import_from_string
    module = importlib.import_module(module_str)
             ^^^^^^^^^^^^^^^^^^^^^^^^^^^^^^^^^^^
  File "/usr/local/lib/python3.12/importlib/__init__.py", line 90, in import_module
    return _bootstrap._gcd_import(name[level:], package, level)
           ^^^^^^^^^^^^^^^^^^^^^^^^^^^^^^^^^^^^^^^^^^^^^^^^^^^^
  File "<frozen importlib._bootstrap>", line 1387, in _gcd_import
  File "<frozen importlib._bootstrap>", line 1360, in _find_and_load
  File "<frozen importlib._bootstrap>", line 1331, in _find_and_load_unlocked
  File "<frozen importlib._bootstrap>", line 935, in _load_unlocked
  File "<frozen importlib._bootstrap_external>", line 999, in exec_module
  File "<frozen importlib._bootstrap>", line 488, in _call_with_frames_removed
  File "/app/graph_service.py", line 4, in <module>
    from archon.archon_graph import agentic_flow
  File "/app/archon/archon_graph.py", line 18, in <module>
    from archon.models.ollama_model import OllamaModel, OllamaClient
  File "/app/archon/models/ollama_model.py", line 6, in <module>
    from pydantic_ai.models.base import BaseAIModel, AIMessage, AIMessageChunk, AIModelT, AIModel
ModuleNotFoundError: No module named 'pydantic_ai.models.base'
WARNING:  WatchFiles detected changes in 'archon/models/ollama_model.py'. Reloading...
WARNING:  WatchFiles detected changes in 'archon/models/ollama_model.py'. Reloading...
Process SpawnProcess-2:
Traceback (most recent call last):
  File "/usr/local/lib/python3.12/multiprocessing/process.py", line 314, in _bootstrap
    self.run()
  File "/usr/local/lib/python3.12/multiprocessing/process.py", line 108, in run
    self._target(*self._args, **self._kwargs)
  File "/usr/local/lib/python3.12/site-packages/uvicorn/_subprocess.py", line 80, in subprocess_started
    target(sockets=sockets)
  File "/usr/local/lib/python3.12/site-packages/uvicorn/server.py", line 66, in run
    return asyncio.run(self.serve(sockets=sockets))
           ^^^^^^^^^^^^^^^^^^^^^^^^^^^^^^^^^^^^^^^^
  File "/usr/local/lib/python3.12/asyncio/runners.py", line 195, in run
    return runner.run(main)
           ^^^^^^^^^^^^^^^^
  File "/usr/local/lib/python3.12/asyncio/runners.py", line 118, in run
    return self._loop.run_until_complete(task)
           ^^^^^^^^^^^^^^^^^^^^^^^^^^^^^^^^^^^
  File "uvloop/loop.pyx", line 1518, in uvloop.loop.Loop.run_until_complete
  File "/usr/local/lib/python3.12/site-packages/uvicorn/server.py", line 70, in serve
    await self._serve(sockets)
  File "/usr/local/lib/python3.12/site-packages/uvicorn/server.py", line 77, in _serve
    config.load()
  File "/usr/local/lib/python3.12/site-packages/uvicorn/config.py", line 435, in load
    self.loaded_app = import_from_string(self.app)
                      ^^^^^^^^^^^^^^^^^^^^^^^^^^^^
  File "/usr/local/lib/python3.12/site-packages/uvicorn/importer.py", line 19, in import_from_string
    module = importlib.import_module(module_str)
             ^^^^^^^^^^^^^^^^^^^^^^^^^^^^^^^^^^^
  File "/usr/local/lib/python3.12/importlib/__init__.py", line 90, in import_module
    return _bootstrap._gcd_import(name[level:], package, level)
           ^^^^^^^^^^^^^^^^^^^^^^^^^^^^^^^^^^^^^^^^^^^^^^^^^^^^
  File "<frozen importlib._bootstrap>", line 1387, in _gcd_import
  File "<frozen importlib._bootstrap>", line 1360, in _find_and_load
  File "<frozen importlib._bootstrap>", line 1331, in _find_and_load_unlocked
  File "<frozen importlib._bootstrap>", line 935, in _load_unlocked
  File "<frozen importlib._bootstrap_external>", line 999, in exec_module
  File "<frozen importlib._bootstrap>", line 488, in _call_with_frames_removed
  File "/app/graph_service.py", line 4, in <module>
    from archon.archon_graph import agentic_flow
  File "/app/archon/archon_graph.py", line 63, in <module>
    from archon.advisor_agent import advisor_agent, AdvisorDeps
  File "/app/archon/advisor_agent.py", line 39, in <module>
    from pydantic_ai.models import register_model
ImportError: cannot import name 'register_model' from 'pydantic_ai.models' (/usr/local/lib/python3.12/site-packages/pydantic_ai/models/__init__.py)
Process SpawnProcess-3:
Traceback (most recent call last):
  File "/usr/local/lib/python3.12/multiprocessing/process.py", line 314, in _bootstrap
    self.run()
  File "/usr/local/lib/python3.12/multiprocessing/process.py", line 108, in run
    self._target(*self._args, **self._kwargs)
  File "/usr/local/lib/python3.12/site-packages/uvicorn/_subprocess.py", line 80, in subprocess_started
    target(sockets=sockets)
  File "/usr/local/lib/python3.12/site-packages/uvicorn/server.py", line 66, in run
    return asyncio.run(self.serve(sockets=sockets))
           ^^^^^^^^^^^^^^^^^^^^^^^^^^^^^^^^^^^^^^^^
  File "/usr/local/lib/python3.12/asyncio/runners.py", line 195, in run
    return runner.run(main)
           ^^^^^^^^^^^^^^^^
  File "/usr/local/lib/python3.12/asyncio/runners.py", line 118, in run
    return self._loop.run_until_complete(task)
           ^^^^^^^^^^^^^^^^^^^^^^^^^^^^^^^^^^^
  File "uvloop/loop.pyx", line 1518, in uvloop.loop.Loop.run_until_complete
  File "/usr/local/lib/python3.12/site-packages/uvicorn/server.py", line 70, in serve
    await self._serve(sockets)
  File "/usr/local/lib/python3.12/site-packages/uvicorn/server.py", line 77, in _serve
    config.load()
  File "/usr/local/lib/python3.12/site-packages/uvicorn/config.py", line 435, in load
    self.loaded_app = import_from_string(self.app)
                      ^^^^^^^^^^^^^^^^^^^^^^^^^^^^
  File "/usr/local/lib/python3.12/site-packages/uvicorn/importer.py", line 19, in import_from_string
    module = importlib.import_module(module_str)
             ^^^^^^^^^^^^^^^^^^^^^^^^^^^^^^^^^^^
  File "/usr/local/lib/python3.12/importlib/__init__.py", line 90, in import_module
    return _bootstrap._gcd_import(name[level:], package, level)
           ^^^^^^^^^^^^^^^^^^^^^^^^^^^^^^^^^^^^^^^^^^^^^^^^^^^^
  File "<frozen importlib._bootstrap>", line 1387, in _gcd_import
  File "<frozen importlib._bootstrap>", line 1360, in _find_and_load
  File "<frozen importlib._bootstrap>", line 1331, in _find_and_load_unlocked
  File "<frozen importlib._bootstrap>", line 935, in _load_unlocked
  File "<frozen importlib._bootstrap_external>", line 999, in exec_module
  File "<frozen importlib._bootstrap>", line 488, in _call_with_frames_removed
  File "/app/graph_service.py", line 4, in <module>
    from archon.archon_graph import agentic_flow
  File "/app/archon/archon_graph.py", line 63, in <module>
    from archon.advisor_agent import advisor_agent, AdvisorDeps
  File "/app/archon/advisor_agent.py", line 39, in <module>
    from pydantic_ai.models import register_model
ImportError: cannot import name 'register_model' from 'pydantic_ai.models' (/usr/local/lib/python3.12/site-packages/pydantic_ai/models/__init__.py)
