INFO:     Will watch for changes in these directories: ['/app']
INFO:     Uvicorn running on http://0.0.0.0:8110 (Press CTRL+C to quit)
INFO:     Started reloader process [11] using WatchFiles
[WARNING] Unable to import advisor_agent, creating stub
Initialized Ollama model 'qwen2.5:latest' with base URL: http://host.docker.internal:11434/v1
Initialized Ollama reasoner model 'qwen2.5:latest' with base URL: http://host.docker.internal:11434/v1
INFO:     Started server process [17]
INFO:     Waiting for application startup.
INFO:     Application startup complete.
INFO:     127.0.0.1:59412 - "GET /health HTTP/1.1" 200 OK
INFO:     127.0.0.1:59428 - "GET /health HTTP/1.1" 200 OK
INFO:     127.0.0.1:44572 - "GET /health HTTP/1.1" 200 OK
INFO:     127.0.0.1:40492 - "GET /health HTTP/1.1" 200 OK
INFO:     127.0.0.1:56014 - "GET /health HTTP/1.1" 200 OK
INFO:     127.0.0.1:40736 - "GET /health HTTP/1.1" 200 OK
INFO:     127.0.0.1:53732 - "GET /health HTTP/1.1" 200 OK
INFO:     127.0.0.1:52492 - "GET /health HTTP/1.1" 200 OK
INFO:     127.0.0.1:54744 - "GET /health HTTP/1.1" 200 OK
INFO:     127.0.0.1:56358 - "GET /health HTTP/1.1" 200 OK
INFO:     127.0.0.1:33404 - "GET /health HTTP/1.1" 200 OK
INFO:     127.0.0.1:44828 - "GET /health HTTP/1.1" 200 OK
INFO:     127.0.0.1:44894 - "GET /health HTTP/1.1" 200 OK
INFO:     127.0.0.1:35758 - "GET /health HTTP/1.1" 200 OK
INFO:     127.0.0.1:53194 - "GET /health HTTP/1.1" 200 OK
INFO:     127.0.0.1:52266 - "GET /health HTTP/1.1" 200 OK
INFO:     127.0.0.1:36028 - "GET /health HTTP/1.1" 200 OK
INFO:     127.0.0.1:49802 - "GET /health HTTP/1.1" 200 OK
INFO:     127.0.0.1:47200 - "GET /health HTTP/1.1" 200 OK
INFO:     127.0.0.1:35168 - "GET /health HTTP/1.1" 200 OK
INFO:     127.0.0.1:37876 - "GET /health HTTP/1.1" 200 OK
INFO:     127.0.0.1:54380 - "GET /health HTTP/1.1" 200 OK
INFO:     127.0.0.1:37114 - "GET /health HTTP/1.1" 200 OK
INFO:     127.0.0.1:44264 - "GET /health HTTP/1.1" 200 OK
INFO:     127.0.0.1:53434 - "GET /health HTTP/1.1" 200 OK
INFO:     127.0.0.1:50366 - "GET /health HTTP/1.1" 200 OK
INFO:     127.0.0.1:52596 - "GET /health HTTP/1.1" 200 OK
INFO:     127.0.0.1:60840 - "GET /health HTTP/1.1" 200 OK
INFO:     127.0.0.1:43332 - "GET /health HTTP/1.1" 200 OK
INFO:     127.0.0.1:34926 - "GET /health HTTP/1.1" 200 OK
INFO:     127.0.0.1:52454 - "GET /health HTTP/1.1" 200 OK
INFO:     127.0.0.1:59644 - "GET /health HTTP/1.1" 200 OK
INFO:     127.0.0.1:37590 - "GET /health HTTP/1.1" 200 OK
INFO:     127.0.0.1:46786 - "GET /health HTTP/1.1" 200 OK
INFO:     127.0.0.1:55918 - "GET /health HTTP/1.1" 200 OK
INFO:     127.0.0.1:53858 - "GET /health HTTP/1.1" 200 OK
INFO:     127.0.0.1:53458 - "GET /health HTTP/1.1" 200 OK
INFO:     127.0.0.1:57500 - "GET /health HTTP/1.1" 200 OK
INFO:     127.0.0.1:41908 - "GET /health HTTP/1.1" 200 OK
INFO:     127.0.0.1:33782 - "GET /health HTTP/1.1" 200 OK
INFO:     127.0.0.1:39784 - "GET /health HTTP/1.1" 200 OK
INFO:     127.0.0.1:46080 - "GET /health HTTP/1.1" 200 OK
INFO:     127.0.0.1:44614 - "GET /health HTTP/1.1" 200 OK
INFO:     127.0.0.1:35746 - "GET /health HTTP/1.1" 200 OK
WARNING:  WatchFiles detected changes in 'update_env_from_profile.py'. Reloading...
INFO:     Shutting down
INFO:     Waiting for application shutdown.
INFO:     Application shutdown complete.
INFO:     Finished server process [17]
[WARNING] Unable to import advisor_agent, creating stub
Initialized Ollama model 'qwen2.5:latest' with base URL: http://host.docker.internal:11434/v1
Initialized Ollama reasoner model 'qwen2.5:latest' with base URL: http://host.docker.internal:11434/v1
INFO:     Started server process [292]
INFO:     Waiting for application startup.
INFO:     Application startup complete.
INFO:     127.0.0.1:44580 - "GET /health HTTP/1.1" 200 OK
INFO:     127.0.0.1:40434 - "GET /health HTTP/1.1" 200 OK
INFO:     127.0.0.1:47448 - "GET /health HTTP/1.1" 200 OK
INFO:     127.0.0.1:50640 - "GET /health HTTP/1.1" 200 OK
WARNING:  WatchFiles detected changes in 'archon/llm_provider.py'. Reloading...
INFO:     Shutting down
INFO:     Waiting for application shutdown.
INFO:     Application shutdown complete.
INFO:     Finished server process [292]
Fichier de configuration introuvable: /workbench/env_vars.json
Fichier de configuration introuvable: /workbench/env_vars.json
Fichier de configuration introuvable: /workbench/env_vars.json
Fichier de configuration introuvable: /workbench/env_vars.json
Fichier de configuration introuvable: /workbench/env_vars.json
[WARNING] Unable to import advisor_agent, creating stub
Initialized Ollama model 'qwen2.5:latest' with base URL: http://host.docker.internal:11434/v1
Initialized Ollama reasoner model 'qwen2.5:latest' with base URL: http://host.docker.internal:11434/v1
INFO:     Started server process [327]
INFO:     Waiting for application startup.
INFO:     Application startup complete.
INFO:     127.0.0.1:41806 - "GET /health HTTP/1.1" 200 OK
INFO:     127.0.0.1:60520 - "GET /health HTTP/1.1" 200 OK
INFO:     127.0.0.1:36194 - "GET /health HTTP/1.1" 200 OK
INFO:     127.0.0.1:47178 - "GET /health HTTP/1.1" 200 OK
INFO:     127.0.0.1:35202 - "GET /health HTTP/1.1" 200 OK
WARNING:  WatchFiles detected changes in 'archon/llm_provider.py'. Reloading...
INFO:     Shutting down
INFO:     Waiting for application shutdown.
INFO:     Application shutdown complete.
INFO:     Finished server process [327]
[WARNING] Unable to import advisor_agent, creating stub
Process SpawnProcess-4:
Traceback (most recent call last):
  File "/usr/local/lib/python3.10/multiprocessing/process.py", line 314, in _bootstrap
    self.run()
  File "/usr/local/lib/python3.10/multiprocessing/process.py", line 108, in run
    self._target(*self._args, **self._kwargs)
  File "/usr/local/lib/python3.10/site-packages/uvicorn/_subprocess.py", line 78, in subprocess_started
    target(sockets=sockets)
  File "/usr/local/lib/python3.10/site-packages/uvicorn/server.py", line 62, in run
    return asyncio.run(self.serve(sockets=sockets))
  File "/usr/local/lib/python3.10/asyncio/runners.py", line 44, in run
    return loop.run_until_complete(main)
  File "/usr/local/lib/python3.10/asyncio/base_events.py", line 649, in run_until_complete
    return future.result()
  File "/usr/local/lib/python3.10/site-packages/uvicorn/server.py", line 69, in serve
    config.load()
  File "/usr/local/lib/python3.10/site-packages/uvicorn/config.py", line 433, in load
    self.loaded_app = import_from_string(self.app)
  File "/usr/local/lib/python3.10/site-packages/uvicorn/importer.py", line 19, in import_from_string
    module = importlib.import_module(module_str)
  File "/usr/local/lib/python3.10/importlib/__init__.py", line 126, in import_module
    return _bootstrap._gcd_import(name[level:], package, level)
  File "<frozen importlib._bootstrap>", line 1050, in _gcd_import
  File "<frozen importlib._bootstrap>", line 1027, in _find_and_load
  File "<frozen importlib._bootstrap>", line 1006, in _find_and_load_unlocked
  File "<frozen importlib._bootstrap>", line 688, in _load_unlocked
  File "<frozen importlib._bootstrap_external>", line 883, in exec_module
  File "<frozen importlib._bootstrap>", line 241, in _call_with_frames_removed
  File "/app/graph_service.py", line 24, in <module>
    from archon_graph import agentic_flow
  File "/app/archon_graph.py", line 127, in <module>
    from archon.refiner_agents.tools_refiner_agent import tools_refiner_agent, ToolsRefinerDeps
  File "/app/archon/refiner_agents/tools_refiner_agent.py", line 56, in <module>
    tools_refiner_agent = Agent(
  File "/usr/local/lib/python3.10/site-packages/pydantic_ai/agent.py", line 290, in __init__
    self.model = models.infer_model(model)
  File "/usr/local/lib/python3.10/site-packages/pydantic_ai/models/__init__.py", line 607, in infer_model
    raise UserError(f'Unknown model: {model}')  # pragma: no cover
pydantic_ai.exceptions.UserError: Unknown model: moonshotai/kimi-k2:free
WARNING:  WatchFiles detected changes in 'archon/llm_provider.py'. Reloading...
[WARNING] Unable to import advisor_agent, creating stub
Process SpawnProcess-5:
Traceback (most recent call last):
  File "/usr/local/lib/python3.10/multiprocessing/process.py", line 314, in _bootstrap
    self.run()
  File "/usr/local/lib/python3.10/multiprocessing/process.py", line 108, in run
    self._target(*self._args, **self._kwargs)
  File "/usr/local/lib/python3.10/site-packages/uvicorn/_subprocess.py", line 78, in subprocess_started
    target(sockets=sockets)
  File "/usr/local/lib/python3.10/site-packages/uvicorn/server.py", line 62, in run
    return asyncio.run(self.serve(sockets=sockets))
  File "/usr/local/lib/python3.10/asyncio/runners.py", line 44, in run
    return loop.run_until_complete(main)
  File "/usr/local/lib/python3.10/asyncio/base_events.py", line 649, in run_until_complete
    return future.result()
  File "/usr/local/lib/python3.10/site-packages/uvicorn/server.py", line 69, in serve
    config.load()
  File "/usr/local/lib/python3.10/site-packages/uvicorn/config.py", line 433, in load
    self.loaded_app = import_from_string(self.app)
  File "/usr/local/lib/python3.10/site-packages/uvicorn/importer.py", line 19, in import_from_string
    module = importlib.import_module(module_str)
  File "/usr/local/lib/python3.10/importlib/__init__.py", line 126, in import_module
    return _bootstrap._gcd_import(name[level:], package, level)
  File "<frozen importlib._bootstrap>", line 1050, in _gcd_import
  File "<frozen importlib._bootstrap>", line 1027, in _find_and_load
  File "<frozen importlib._bootstrap>", line 1006, in _find_and_load_unlocked
  File "<frozen importlib._bootstrap>", line 688, in _load_unlocked
  File "<frozen importlib._bootstrap_external>", line 883, in exec_module
  File "<frozen importlib._bootstrap>", line 241, in _call_with_frames_removed
  File "/app/graph_service.py", line 24, in <module>
    from archon_graph import agentic_flow
  File "/app/archon_graph.py", line 127, in <module>
    from archon.refiner_agents.tools_refiner_agent import tools_refiner_agent, ToolsRefinerDeps
  File "/app/archon/refiner_agents/tools_refiner_agent.py", line 56, in <module>
    tools_refiner_agent = Agent(
  File "/usr/local/lib/python3.10/site-packages/pydantic_ai/agent.py", line 290, in __init__
    self.model = models.infer_model(model)
  File "/usr/local/lib/python3.10/site-packages/pydantic_ai/models/__init__.py", line 607, in infer_model
    raise UserError(f'Unknown model: {model}')  # pragma: no cover
pydantic_ai.exceptions.UserError: Unknown model: moonshotai/kimi-k2:free
WARNING:  WatchFiles detected changes in 'archon/llm_provider.py'. Reloading...
[WARNING] Unable to import advisor_agent, creating stub
Process SpawnProcess-6:
Traceback (most recent call last):
  File "/usr/local/lib/python3.10/multiprocessing/process.py", line 314, in _bootstrap
    self.run()
  File "/usr/local/lib/python3.10/multiprocessing/process.py", line 108, in run
    self._target(*self._args, **self._kwargs)
  File "/usr/local/lib/python3.10/site-packages/uvicorn/_subprocess.py", line 78, in subprocess_started
    target(sockets=sockets)
  File "/usr/local/lib/python3.10/site-packages/uvicorn/server.py", line 62, in run
    return asyncio.run(self.serve(sockets=sockets))
  File "/usr/local/lib/python3.10/asyncio/runners.py", line 44, in run
    return loop.run_until_complete(main)
  File "/usr/local/lib/python3.10/asyncio/base_events.py", line 649, in run_until_complete
    return future.result()
  File "/usr/local/lib/python3.10/site-packages/uvicorn/server.py", line 69, in serve
    config.load()
  File "/usr/local/lib/python3.10/site-packages/uvicorn/config.py", line 433, in load
    self.loaded_app = import_from_string(self.app)
  File "/usr/local/lib/python3.10/site-packages/uvicorn/importer.py", line 19, in import_from_string
    module = importlib.import_module(module_str)
  File "/usr/local/lib/python3.10/importlib/__init__.py", line 126, in import_module
    return _bootstrap._gcd_import(name[level:], package, level)
  File "<frozen importlib._bootstrap>", line 1050, in _gcd_import
  File "<frozen importlib._bootstrap>", line 1027, in _find_and_load
  File "<frozen importlib._bootstrap>", line 1006, in _find_and_load_unlocked
  File "<frozen importlib._bootstrap>", line 688, in _load_unlocked
  File "<frozen importlib._bootstrap_external>", line 883, in exec_module
  File "<frozen importlib._bootstrap>", line 241, in _call_with_frames_removed
  File "/app/graph_service.py", line 24, in <module>
    from archon_graph import agentic_flow
  File "/app/archon_graph.py", line 127, in <module>
    from archon.refiner_agents.tools_refiner_agent import tools_refiner_agent, ToolsRefinerDeps
  File "/app/archon/refiner_agents/tools_refiner_agent.py", line 56, in <module>
    tools_refiner_agent = Agent(
  File "/usr/local/lib/python3.10/site-packages/pydantic_ai/agent.py", line 290, in __init__
    self.model = models.infer_model(model)
  File "/usr/local/lib/python3.10/site-packages/pydantic_ai/models/__init__.py", line 607, in infer_model
    raise UserError(f'Unknown model: {model}')  # pragma: no cover
pydantic_ai.exceptions.UserError: Unknown model: moonshotai/kimi-k2:free
WARNING:  WatchFiles detected changes in 'archon/llm_provider.py'. Reloading...
[WARNING] Unable to import advisor_agent, creating stub
Process SpawnProcess-7:
Traceback (most recent call last):
  File "/usr/local/lib/python3.10/multiprocessing/process.py", line 314, in _bootstrap
    self.run()
  File "/usr/local/lib/python3.10/multiprocessing/process.py", line 108, in run
    self._target(*self._args, **self._kwargs)
  File "/usr/local/lib/python3.10/site-packages/uvicorn/_subprocess.py", line 78, in subprocess_started
    target(sockets=sockets)
  File "/usr/local/lib/python3.10/site-packages/uvicorn/server.py", line 62, in run
    return asyncio.run(self.serve(sockets=sockets))
  File "/usr/local/lib/python3.10/asyncio/runners.py", line 44, in run
    return loop.run_until_complete(main)
  File "/usr/local/lib/python3.10/asyncio/base_events.py", line 649, in run_until_complete
    return future.result()
  File "/usr/local/lib/python3.10/site-packages/uvicorn/server.py", line 69, in serve
    config.load()
  File "/usr/local/lib/python3.10/site-packages/uvicorn/config.py", line 433, in load
    self.loaded_app = import_from_string(self.app)
  File "/usr/local/lib/python3.10/site-packages/uvicorn/importer.py", line 19, in import_from_string
    module = importlib.import_module(module_str)
  File "/usr/local/lib/python3.10/importlib/__init__.py", line 126, in import_module
    return _bootstrap._gcd_import(name[level:], package, level)
  File "<frozen importlib._bootstrap>", line 1050, in _gcd_import
  File "<frozen importlib._bootstrap>", line 1027, in _find_and_load
  File "<frozen importlib._bootstrap>", line 1006, in _find_and_load_unlocked
  File "<frozen importlib._bootstrap>", line 688, in _load_unlocked
  File "<frozen importlib._bootstrap_external>", line 883, in exec_module
  File "<frozen importlib._bootstrap>", line 241, in _call_with_frames_removed
  File "/app/graph_service.py", line 24, in <module>
    from archon_graph import agentic_flow
  File "/app/archon_graph.py", line 127, in <module>
    from archon.refiner_agents.tools_refiner_agent import tools_refiner_agent, ToolsRefinerDeps
  File "/app/archon/refiner_agents/tools_refiner_agent.py", line 56, in <module>
    tools_refiner_agent = Agent(
  File "/usr/local/lib/python3.10/site-packages/pydantic_ai/agent.py", line 290, in __init__
    self.model = models.infer_model(model)
  File "/usr/local/lib/python3.10/site-packages/pydantic_ai/models/__init__.py", line 607, in infer_model
    raise UserError(f'Unknown model: {model}')  # pragma: no cover
pydantic_ai.exceptions.UserError: Unknown model: moonshotai/kimi-k2:free
WARNING:  WatchFiles detected changes in 'archon/llm_provider.py'. Reloading...
[WARNING] Unable to import advisor_agent, creating stub
Process SpawnProcess-8:
Traceback (most recent call last):
  File "/usr/local/lib/python3.10/multiprocessing/process.py", line 314, in _bootstrap
    self.run()
  File "/usr/local/lib/python3.10/multiprocessing/process.py", line 108, in run
    self._target(*self._args, **self._kwargs)
  File "/usr/local/lib/python3.10/site-packages/uvicorn/_subprocess.py", line 78, in subprocess_started
    target(sockets=sockets)
  File "/usr/local/lib/python3.10/site-packages/uvicorn/server.py", line 62, in run
    return asyncio.run(self.serve(sockets=sockets))
  File "/usr/local/lib/python3.10/asyncio/runners.py", line 44, in run
    return loop.run_until_complete(main)
  File "/usr/local/lib/python3.10/asyncio/base_events.py", line 649, in run_until_complete
    return future.result()
  File "/usr/local/lib/python3.10/site-packages/uvicorn/server.py", line 69, in serve
    config.load()
  File "/usr/local/lib/python3.10/site-packages/uvicorn/config.py", line 433, in load
    self.loaded_app = import_from_string(self.app)
  File "/usr/local/lib/python3.10/site-packages/uvicorn/importer.py", line 19, in import_from_string
    module = importlib.import_module(module_str)
  File "/usr/local/lib/python3.10/importlib/__init__.py", line 126, in import_module
    return _bootstrap._gcd_import(name[level:], package, level)
  File "<frozen importlib._bootstrap>", line 1050, in _gcd_import
  File "<frozen importlib._bootstrap>", line 1027, in _find_and_load
  File "<frozen importlib._bootstrap>", line 1006, in _find_and_load_unlocked
  File "<frozen importlib._bootstrap>", line 688, in _load_unlocked
  File "<frozen importlib._bootstrap_external>", line 883, in exec_module
  File "<frozen importlib._bootstrap>", line 241, in _call_with_frames_removed
  File "/app/graph_service.py", line 24, in <module>
    from archon_graph import agentic_flow
  File "/app/archon_graph.py", line 127, in <module>
    from archon.refiner_agents.tools_refiner_agent import tools_refiner_agent, ToolsRefinerDeps
  File "/app/archon/refiner_agents/tools_refiner_agent.py", line 56, in <module>
    tools_refiner_agent = Agent(
  File "/usr/local/lib/python3.10/site-packages/pydantic_ai/agent.py", line 290, in __init__
    self.model = models.infer_model(model)
  File "/usr/local/lib/python3.10/site-packages/pydantic_ai/models/__init__.py", line 607, in infer_model
    raise UserError(f'Unknown model: {model}')  # pragma: no cover
pydantic_ai.exceptions.UserError: Unknown model: moonshotai/kimi-k2:free
WARNING:  WatchFiles detected changes in 'archon/llm_provider.py'. Reloading...
[WARNING] Unable to import advisor_agent, creating stub
Process SpawnProcess-9:
Traceback (most recent call last):
  File "/usr/local/lib/python3.10/multiprocessing/process.py", line 314, in _bootstrap
    self.run()
  File "/usr/local/lib/python3.10/multiprocessing/process.py", line 108, in run
    self._target(*self._args, **self._kwargs)
  File "/usr/local/lib/python3.10/site-packages/uvicorn/_subprocess.py", line 78, in subprocess_started
    target(sockets=sockets)
  File "/usr/local/lib/python3.10/site-packages/uvicorn/server.py", line 62, in run
    return asyncio.run(self.serve(sockets=sockets))
  File "/usr/local/lib/python3.10/asyncio/runners.py", line 44, in run
    return loop.run_until_complete(main)
  File "/usr/local/lib/python3.10/asyncio/base_events.py", line 649, in run_until_complete
    return future.result()
  File "/usr/local/lib/python3.10/site-packages/uvicorn/server.py", line 69, in serve
    config.load()
  File "/usr/local/lib/python3.10/site-packages/uvicorn/config.py", line 433, in load
    self.loaded_app = import_from_string(self.app)
  File "/usr/local/lib/python3.10/site-packages/uvicorn/importer.py", line 19, in import_from_string
    module = importlib.import_module(module_str)
  File "/usr/local/lib/python3.10/importlib/__init__.py", line 126, in import_module
    return _bootstrap._gcd_import(name[level:], package, level)
  File "<frozen importlib._bootstrap>", line 1050, in _gcd_import
  File "<frozen importlib._bootstrap>", line 1027, in _find_and_load
  File "<frozen importlib._bootstrap>", line 1006, in _find_and_load_unlocked
  File "<frozen importlib._bootstrap>", line 688, in _load_unlocked
  File "<frozen importlib._bootstrap_external>", line 883, in exec_module
  File "<frozen importlib._bootstrap>", line 241, in _call_with_frames_removed
  File "/app/graph_service.py", line 24, in <module>
    from archon_graph import agentic_flow
  File "/app/archon_graph.py", line 127, in <module>
    from archon.refiner_agents.tools_refiner_agent import tools_refiner_agent, ToolsRefinerDeps
  File "/app/archon/refiner_agents/tools_refiner_agent.py", line 56, in <module>
    tools_refiner_agent = Agent(
  File "/usr/local/lib/python3.10/site-packages/pydantic_ai/agent.py", line 290, in __init__
    self.model = models.infer_model(model)
  File "/usr/local/lib/python3.10/site-packages/pydantic_ai/models/__init__.py", line 607, in infer_model
    raise UserError(f'Unknown model: {model}')  # pragma: no cover
pydantic_ai.exceptions.UserError: Unknown model: moonshotai/kimi-k2:free
WARNING:  WatchFiles detected changes in 'archon/llm_provider.py'. Reloading...
[WARNING] Unable to import advisor_agent, creating stub
Process SpawnProcess-10:
Traceback (most recent call last):
  File "/usr/local/lib/python3.10/multiprocessing/process.py", line 314, in _bootstrap
    self.run()
  File "/usr/local/lib/python3.10/multiprocessing/process.py", line 108, in run
    self._target(*self._args, **self._kwargs)
  File "/usr/local/lib/python3.10/site-packages/uvicorn/_subprocess.py", line 78, in subprocess_started
    target(sockets=sockets)
  File "/usr/local/lib/python3.10/site-packages/uvicorn/server.py", line 62, in run
    return asyncio.run(self.serve(sockets=sockets))
  File "/usr/local/lib/python3.10/asyncio/runners.py", line 44, in run
    return loop.run_until_complete(main)
  File "/usr/local/lib/python3.10/asyncio/base_events.py", line 649, in run_until_complete
    return future.result()
  File "/usr/local/lib/python3.10/site-packages/uvicorn/server.py", line 69, in serve
    config.load()
  File "/usr/local/lib/python3.10/site-packages/uvicorn/config.py", line 433, in load
    self.loaded_app = import_from_string(self.app)
  File "/usr/local/lib/python3.10/site-packages/uvicorn/importer.py", line 19, in import_from_string
    module = importlib.import_module(module_str)
  File "/usr/local/lib/python3.10/importlib/__init__.py", line 126, in import_module
    return _bootstrap._gcd_import(name[level:], package, level)
  File "<frozen importlib._bootstrap>", line 1050, in _gcd_import
  File "<frozen importlib._bootstrap>", line 1027, in _find_and_load
  File "<frozen importlib._bootstrap>", line 1006, in _find_and_load_unlocked
  File "<frozen importlib._bootstrap>", line 688, in _load_unlocked
  File "<frozen importlib._bootstrap_external>", line 883, in exec_module
  File "<frozen importlib._bootstrap>", line 241, in _call_with_frames_removed
  File "/app/graph_service.py", line 24, in <module>
    from archon_graph import agentic_flow
  File "/app/archon_graph.py", line 127, in <module>
    from archon.refiner_agents.tools_refiner_agent import tools_refiner_agent, ToolsRefinerDeps
  File "/app/archon/refiner_agents/tools_refiner_agent.py", line 56, in <module>
    tools_refiner_agent = Agent(
  File "/usr/local/lib/python3.10/site-packages/pydantic_ai/agent.py", line 290, in __init__
    self.model = models.infer_model(model)
  File "/usr/local/lib/python3.10/site-packages/pydantic_ai/models/__init__.py", line 607, in infer_model
    raise UserError(f'Unknown model: {model}')  # pragma: no cover
pydantic_ai.exceptions.UserError: Unknown model: moonshotai/kimi-k2:free
WARNING:  WatchFiles detected changes in 'archon/llm_provider.py'. Reloading...
[WARNING] Unable to import advisor_agent, creating stub
Process SpawnProcess-11:
Traceback (most recent call last):
  File "/usr/local/lib/python3.10/multiprocessing/process.py", line 314, in _bootstrap
    self.run()
  File "/usr/local/lib/python3.10/multiprocessing/process.py", line 108, in run
    self._target(*self._args, **self._kwargs)
  File "/usr/local/lib/python3.10/site-packages/uvicorn/_subprocess.py", line 78, in subprocess_started
    target(sockets=sockets)
  File "/usr/local/lib/python3.10/site-packages/uvicorn/server.py", line 62, in run
    return asyncio.run(self.serve(sockets=sockets))
  File "/usr/local/lib/python3.10/asyncio/runners.py", line 44, in run
    return loop.run_until_complete(main)
  File "/usr/local/lib/python3.10/asyncio/base_events.py", line 649, in run_until_complete
    return future.result()
  File "/usr/local/lib/python3.10/site-packages/uvicorn/server.py", line 69, in serve
    config.load()
  File "/usr/local/lib/python3.10/site-packages/uvicorn/config.py", line 433, in load
    self.loaded_app = import_from_string(self.app)
  File "/usr/local/lib/python3.10/site-packages/uvicorn/importer.py", line 19, in import_from_string
    module = importlib.import_module(module_str)
  File "/usr/local/lib/python3.10/importlib/__init__.py", line 126, in import_module
    return _bootstrap._gcd_import(name[level:], package, level)
  File "<frozen importlib._bootstrap>", line 1050, in _gcd_import
  File "<frozen importlib._bootstrap>", line 1027, in _find_and_load
  File "<frozen importlib._bootstrap>", line 1006, in _find_and_load_unlocked
  File "<frozen importlib._bootstrap>", line 688, in _load_unlocked
  File "<frozen importlib._bootstrap_external>", line 883, in exec_module
  File "<frozen importlib._bootstrap>", line 241, in _call_with_frames_removed
  File "/app/graph_service.py", line 24, in <module>
    from archon_graph import agentic_flow
  File "/app/archon_graph.py", line 127, in <module>
    from archon.refiner_agents.tools_refiner_agent import tools_refiner_agent, ToolsRefinerDeps
  File "/app/archon/refiner_agents/tools_refiner_agent.py", line 56, in <module>
    tools_refiner_agent = Agent(
  File "/usr/local/lib/python3.10/site-packages/pydantic_ai/agent.py", line 290, in __init__
    self.model = models.infer_model(model)
  File "/usr/local/lib/python3.10/site-packages/pydantic_ai/models/__init__.py", line 607, in infer_model
    raise UserError(f'Unknown model: {model}')  # pragma: no cover
pydantic_ai.exceptions.UserError: Unknown model: moonshotai/kimi-k2:free
WARNING:  WatchFiles detected changes in 'archon/llm_provider.py'. Reloading...
[WARNING] Unable to import advisor_agent, creating stub
Process SpawnProcess-12:
Traceback (most recent call last):
  File "/usr/local/lib/python3.10/multiprocessing/process.py", line 314, in _bootstrap
    self.run()
  File "/usr/local/lib/python3.10/multiprocessing/process.py", line 108, in run
    self._target(*self._args, **self._kwargs)
  File "/usr/local/lib/python3.10/site-packages/uvicorn/_subprocess.py", line 78, in subprocess_started
    target(sockets=sockets)
  File "/usr/local/lib/python3.10/site-packages/uvicorn/server.py", line 62, in run
    return asyncio.run(self.serve(sockets=sockets))
  File "/usr/local/lib/python3.10/asyncio/runners.py", line 44, in run
    return loop.run_until_complete(main)
  File "/usr/local/lib/python3.10/asyncio/base_events.py", line 649, in run_until_complete
    return future.result()
  File "/usr/local/lib/python3.10/site-packages/uvicorn/server.py", line 69, in serve
    config.load()
  File "/usr/local/lib/python3.10/site-packages/uvicorn/config.py", line 433, in load
    self.loaded_app = import_from_string(self.app)
  File "/usr/local/lib/python3.10/site-packages/uvicorn/importer.py", line 19, in import_from_string
    module = importlib.import_module(module_str)
  File "/usr/local/lib/python3.10/importlib/__init__.py", line 126, in import_module
    return _bootstrap._gcd_import(name[level:], package, level)
  File "<frozen importlib._bootstrap>", line 1050, in _gcd_import
  File "<frozen importlib._bootstrap>", line 1027, in _find_and_load
  File "<frozen importlib._bootstrap>", line 1006, in _find_and_load_unlocked
  File "<frozen importlib._bootstrap>", line 688, in _load_unlocked
  File "<frozen importlib._bootstrap_external>", line 883, in exec_module
  File "<frozen importlib._bootstrap>", line 241, in _call_with_frames_removed
  File "/app/graph_service.py", line 24, in <module>
    from archon_graph import agentic_flow
  File "/app/archon_graph.py", line 127, in <module>
    from archon.refiner_agents.tools_refiner_agent import tools_refiner_agent, ToolsRefinerDeps
  File "/app/archon/refiner_agents/tools_refiner_agent.py", line 56, in <module>
    tools_refiner_agent = Agent(
  File "/usr/local/lib/python3.10/site-packages/pydantic_ai/agent.py", line 290, in __init__
    self.model = models.infer_model(model)
  File "/usr/local/lib/python3.10/site-packages/pydantic_ai/models/__init__.py", line 607, in infer_model
    raise UserError(f'Unknown model: {model}')  # pragma: no cover
pydantic_ai.exceptions.UserError: Unknown model: moonshotai/kimi-k2:free
WARNING:  WatchFiles detected changes in 'archon/llm_provider.py'. Reloading...
[WARNING] Unable to import advisor_agent, creating stub
Process SpawnProcess-13:
Traceback (most recent call last):
  File "/usr/local/lib/python3.10/multiprocessing/process.py", line 314, in _bootstrap
    self.run()
  File "/usr/local/lib/python3.10/multiprocessing/process.py", line 108, in run
    self._target(*self._args, **self._kwargs)
  File "/usr/local/lib/python3.10/site-packages/uvicorn/_subprocess.py", line 78, in subprocess_started
    target(sockets=sockets)
  File "/usr/local/lib/python3.10/site-packages/uvicorn/server.py", line 62, in run
    return asyncio.run(self.serve(sockets=sockets))
  File "/usr/local/lib/python3.10/asyncio/runners.py", line 44, in run
    return loop.run_until_complete(main)
  File "/usr/local/lib/python3.10/asyncio/base_events.py", line 649, in run_until_complete
    return future.result()
  File "/usr/local/lib/python3.10/site-packages/uvicorn/server.py", line 69, in serve
    config.load()
  File "/usr/local/lib/python3.10/site-packages/uvicorn/config.py", line 433, in load
    self.loaded_app = import_from_string(self.app)
  File "/usr/local/lib/python3.10/site-packages/uvicorn/importer.py", line 19, in import_from_string
    module = importlib.import_module(module_str)
  File "/usr/local/lib/python3.10/importlib/__init__.py", line 126, in import_module
    return _bootstrap._gcd_import(name[level:], package, level)
  File "<frozen importlib._bootstrap>", line 1050, in _gcd_import
  File "<frozen importlib._bootstrap>", line 1027, in _find_and_load
  File "<frozen importlib._bootstrap>", line 1006, in _find_and_load_unlocked
  File "<frozen importlib._bootstrap>", line 688, in _load_unlocked
  File "<frozen importlib._bootstrap_external>", line 883, in exec_module
  File "<frozen importlib._bootstrap>", line 241, in _call_with_frames_removed
  File "/app/graph_service.py", line 24, in <module>
    from archon_graph import agentic_flow
  File "/app/archon_graph.py", line 127, in <module>
    from archon.refiner_agents.tools_refiner_agent import tools_refiner_agent, ToolsRefinerDeps
  File "/app/archon/refiner_agents/tools_refiner_agent.py", line 56, in <module>
    tools_refiner_agent = Agent(
  File "/usr/local/lib/python3.10/site-packages/pydantic_ai/agent.py", line 290, in __init__
    self.model = models.infer_model(model)
  File "/usr/local/lib/python3.10/site-packages/pydantic_ai/models/__init__.py", line 607, in infer_model
    raise UserError(f'Unknown model: {model}')  # pragma: no cover
pydantic_ai.exceptions.UserError: Unknown model: moonshotai/kimi-k2:free
WARNING:  WatchFiles detected changes in 'archon/llm_provider.py'. Reloading...
[WARNING] Unable to import advisor_agent, creating stub
Process SpawnProcess-14:
Traceback (most recent call last):
  File "/usr/local/lib/python3.10/multiprocessing/process.py", line 314, in _bootstrap
    self.run()
  File "/usr/local/lib/python3.10/multiprocessing/process.py", line 108, in run
    self._target(*self._args, **self._kwargs)
  File "/usr/local/lib/python3.10/site-packages/uvicorn/_subprocess.py", line 78, in subprocess_started
    target(sockets=sockets)
  File "/usr/local/lib/python3.10/site-packages/uvicorn/server.py", line 62, in run
    return asyncio.run(self.serve(sockets=sockets))
  File "/usr/local/lib/python3.10/asyncio/runners.py", line 44, in run
    return loop.run_until_complete(main)
  File "/usr/local/lib/python3.10/asyncio/base_events.py", line 649, in run_until_complete
    return future.result()
  File "/usr/local/lib/python3.10/site-packages/uvicorn/server.py", line 69, in serve
    config.load()
  File "/usr/local/lib/python3.10/site-packages/uvicorn/config.py", line 433, in load
    self.loaded_app = import_from_string(self.app)
  File "/usr/local/lib/python3.10/site-packages/uvicorn/importer.py", line 19, in import_from_string
    module = importlib.import_module(module_str)
  File "/usr/local/lib/python3.10/importlib/__init__.py", line 126, in import_module
    return _bootstrap._gcd_import(name[level:], package, level)
  File "<frozen importlib._bootstrap>", line 1050, in _gcd_import
  File "<frozen importlib._bootstrap>", line 1027, in _find_and_load
  File "<frozen importlib._bootstrap>", line 1006, in _find_and_load_unlocked
  File "<frozen importlib._bootstrap>", line 688, in _load_unlocked
  File "<frozen importlib._bootstrap_external>", line 883, in exec_module
  File "<frozen importlib._bootstrap>", line 241, in _call_with_frames_removed
  File "/app/graph_service.py", line 24, in <module>
    from archon_graph import agentic_flow
  File "/app/archon_graph.py", line 127, in <module>
    from archon.refiner_agents.tools_refiner_agent import tools_refiner_agent, ToolsRefinerDeps
  File "/app/archon/refiner_agents/tools_refiner_agent.py", line 56, in <module>
    tools_refiner_agent = Agent(
  File "/usr/local/lib/python3.10/site-packages/pydantic_ai/agent.py", line 290, in __init__
    self.model = models.infer_model(model)
  File "/usr/local/lib/python3.10/site-packages/pydantic_ai/models/__init__.py", line 607, in infer_model
    raise UserError(f'Unknown model: {model}')  # pragma: no cover
pydantic_ai.exceptions.UserError: Unknown model: moonshotai/kimi-k2:free
WARNING:  WatchFiles detected changes in 'archon/llm_provider.py'. Reloading...
[WARNING] Unable to import advisor_agent, creating stub
Process SpawnProcess-15:
Traceback (most recent call last):
  File "/usr/local/lib/python3.10/multiprocessing/process.py", line 314, in _bootstrap
    self.run()
  File "/usr/local/lib/python3.10/multiprocessing/process.py", line 108, in run
    self._target(*self._args, **self._kwargs)
  File "/usr/local/lib/python3.10/site-packages/uvicorn/_subprocess.py", line 78, in subprocess_started
    target(sockets=sockets)
  File "/usr/local/lib/python3.10/site-packages/uvicorn/server.py", line 62, in run
    return asyncio.run(self.serve(sockets=sockets))
  File "/usr/local/lib/python3.10/asyncio/runners.py", line 44, in run
    return loop.run_until_complete(main)
  File "/usr/local/lib/python3.10/asyncio/base_events.py", line 649, in run_until_complete
    return future.result()
  File "/usr/local/lib/python3.10/site-packages/uvicorn/server.py", line 69, in serve
    config.load()
  File "/usr/local/lib/python3.10/site-packages/uvicorn/config.py", line 433, in load
    self.loaded_app = import_from_string(self.app)
  File "/usr/local/lib/python3.10/site-packages/uvicorn/importer.py", line 19, in import_from_string
    module = importlib.import_module(module_str)
  File "/usr/local/lib/python3.10/importlib/__init__.py", line 126, in import_module
    return _bootstrap._gcd_import(name[level:], package, level)
  File "<frozen importlib._bootstrap>", line 1050, in _gcd_import
  File "<frozen importlib._bootstrap>", line 1027, in _find_and_load
  File "<frozen importlib._bootstrap>", line 1006, in _find_and_load_unlocked
  File "<frozen importlib._bootstrap>", line 688, in _load_unlocked
  File "<frozen importlib._bootstrap_external>", line 883, in exec_module
  File "<frozen importlib._bootstrap>", line 241, in _call_with_frames_removed
  File "/app/graph_service.py", line 24, in <module>
    from archon_graph import agentic_flow
  File "/app/archon_graph.py", line 127, in <module>
    from archon.refiner_agents.tools_refiner_agent import tools_refiner_agent, ToolsRefinerDeps
  File "/app/archon/refiner_agents/tools_refiner_agent.py", line 56, in <module>
    tools_refiner_agent = Agent(
  File "/usr/local/lib/python3.10/site-packages/pydantic_ai/agent.py", line 290, in __init__
    self.model = models.infer_model(model)
  File "/usr/local/lib/python3.10/site-packages/pydantic_ai/models/__init__.py", line 607, in infer_model
    raise UserError(f'Unknown model: {model}')  # pragma: no cover
pydantic_ai.exceptions.UserError: Unknown model: moonshotai/kimi-k2:free
